<sdf version='1.7'>
  <world name='default'>
    <light name='sun' type='directional'>
      <cast_shadows>1</cast_shadows>
      <pose>0 0 10 0 -0 0</pose>
      <diffuse>0.8 0.8 0.8 1</diffuse>
      <specular>0.2 0.2 0.2 1</specular>
      <attenuation>
        <range>1000</range>
        <constant>0.9</constant>
        <linear>0.01</linear>
        <quadratic>0.001</quadratic>
      </attenuation>
      <direction>-0.5 0.1 -0.9</direction>
      <spot>
        <inner_angle>0</inner_angle>
        <outer_angle>0</outer_angle>
        <falloff>0</falloff>
      </spot>
    </light>
    <model name='ground_plane'>
      <static>1</static>
      <link name='link'>
        <collision name='collision'>
          <geometry>
            <plane>
              <normal>0 0 1</normal>
              <size>100 100</size>
            </plane>
          </geometry>
          <surface>
            <contact>
              <collide_bitmask>65535</collide_bitmask>
              <ode/>
            </contact>
            <friction>
              <ode>
                <mu>100</mu>
                <mu2>50</mu2>
              </ode>
              <torsional>
                <ode/>
              </torsional>
            </friction>
            <bounce/>
          </surface>
          <max_contacts>10</max_contacts>
        </collision>
        <visual name='visual'>
          <cast_shadows>0</cast_shadows>
          <geometry>
            <plane>
              <normal>0 0 1</normal>
              <size>100 100</size>
            </plane>
          </geometry>
          <material>
            <script>
              <uri>file://media/materials/scripts/gazebo.material</uri>
              <name>Gazebo/Grey</name>
            </script>
          </material>
        </visual>
        <self_collide>0</self_collide>
        <enable_wind>0</enable_wind>
        <kinematic>0</kinematic>
      </link>
    </model>
    <gravity>0 0 -9.8</gravity>
    <magnetic_field>6e-06 2.3e-05 -4.2e-05</magnetic_field>
    <atmosphere type='adiabatic'/>
    <physics type='ode'>
      <max_step_size>0.001</max_step_size>
      <real_time_factor>1</real_time_factor>
      <real_time_update_rate>1000</real_time_update_rate>
    </physics>
    <scene>
      <ambient>0.4 0.4 0.4 1</ambient>
      <background>0.7 0.7 0.7 1</background>
      <shadows>1</shadows>
    </scene>
    <wind/>
    <spherical_coordinates>
      <surface_model>EARTH_WGS84</surface_model>
      <latitude_deg>0</latitude_deg>
      <longitude_deg>0</longitude_deg>
      <elevation>0</elevation>
      <heading_deg>0</heading_deg>
    </spherical_coordinates>
    <model name='arche_urdf'>
      <link name='base_link'>
        <inertial>
          <pose>-0 0.037236 -0.020468 0 -0 0</pose>
          <mass>26.1518</mass>
          <inertia>
            <ixx>0.255196</ixx>
            <ixy>0</ixy>
            <ixz>0</ixz>
            <iyy>0.382972</iyy>
            <iyz>-3.2e-05</iyz>
            <izz>0.614376</izz>
          </inertia>
        </inertial>
        <collision name='base_link_collision'>
          <pose>0 0 0 0 -0 0</pose>
          <geometry>
            <mesh>
              <scale>0.001 0.001 0.001</scale>
              <uri>/home/arche/catkin_ws/src/arche_urdf_description/meshes/base_link.stl</uri>
            </mesh>
          </geometry>
          <surface>
            <contact>
              <ode/>
            </contact>
            <friction>
              <ode>
                <mu>0.2</mu>
                <mu2>0.2</mu2>
              </ode>
              <torsional>
                <ode/>
              </torsional>
            </friction>
            <bounce/>
          </surface>
          <max_contacts>10</max_contacts>
        </collision>
        <visual name='base_link_visual'>
          <pose>0 0 0 0 -0 0</pose>
          <geometry>
            <mesh>
              <scale>0.001 0.001 0.001</scale>
              <uri>/home/arche/catkin_ws/src/arche_urdf_description/meshes/base_link.stl</uri>
            </mesh>
          </geometry>
          <material>
            <script>
              <name>Gazebo/Silver</name>
              <uri>file://media/materials/scripts/gazebo.material</uri>
            </script>
          </material>
        </visual>
        <self_collide>1</self_collide>
        <gravity>1</gravity>
        <enable_wind>0</enable_wind>
        <kinematic>0</kinematic>
      </link>
      <joint name='wheel_1_joint' type='revolute'>
        <pose relative_to='base_link'>0.0916 -0.090246 -0.018979 0 -0 0</pose>
        <parent>base_link</parent>
        <child>wheel_1</child>
        <axis>
          <xyz>1 0 0</xyz>
          <limit>
            <lower>-1e+16</lower>
            <upper>1e+16</upper>
          </limit>
          <dynamics>
            <spring_reference>0</spring_reference>
            <spring_stiffness>0</spring_stiffness>
          </dynamics>
        </axis>
      </joint>
      <link name='wheel_1'>
        <pose relative_to='wheel_1_joint'>0 0 0 0 -0 0</pose>
        <inertial>
          <pose>0.03 0 0 0 -0 0</pose>
          <mass>2.65079</mass>
          <inertia>
            <ixx>0.002376</ixx>
            <ixy>0</ixy>
            <ixz>0</ixz>
            <iyy>0.001972</iyy>
            <iyz>0</iyz>
            <izz>0.001972</izz>
          </inertia>
        </inertial>
        <collision name='wheel_1_collision'>
          <pose>-0.0916 0.090246 0.018979 0 -0 0</pose>
          <geometry>
            <mesh>
              <scale>0.001 0.001 0.001</scale>
              <uri>/home/arche/catkin_ws/src/arche_urdf_description/meshes/wheel_1.stl</uri>
            </mesh>
          </geometry>
          <surface>
            <contact>
              <ode/>
            </contact>
            <friction>
              <ode>
                <mu>0.2</mu>
                <mu2>0.2</mu2>
              </ode>
              <torsional>
                <ode/>
              </torsional>
            </friction>
            <bounce/>
          </surface>
          <max_contacts>10</max_contacts>
        </collision>
        <visual name='wheel_1_visual'>
          <pose>-0.0916 0.090246 0.018979 0 -0 0</pose>
          <geometry>
            <mesh>
              <scale>0.001 0.001 0.001</scale>
              <uri>/home/arche/catkin_ws/src/arche_urdf_description/meshes/wheel_1.stl</uri>
            </mesh>
          </geometry>
          <material>
            <script>
              <name>Gazebo/Silver</name>
              <uri>file://media/materials/scripts/gazebo.material</uri>
            </script>
          </material>
        </visual>
        <self_collide>1</self_collide>
        <enable_wind>0</enable_wind>
        <kinematic>0</kinematic>
      </link>
      <joint name='wheel_2_joint' type='revolute'>
        <pose relative_to='base_link'>-0.0916 -0.090246 -0.018979 0 -0 0</pose>
        <parent>base_link</parent>
        <child>wheel_2</child>
        <axis>
          <xyz>-1 0 0</xyz>
          <limit>
            <lower>-1e+16</lower>
            <upper>1e+16</upper>
          </limit>
          <dynamics>
            <spring_reference>0</spring_reference>
            <spring_stiffness>0</spring_stiffness>
          </dynamics>
        </axis>
      </joint>
      <link name='wheel_2'>
        <pose relative_to='wheel_2_joint'>0 0 0 0 -0 0</pose>
        <inertial>
          <pose>-0.03 0 0 0 -0 0</pose>
          <mass>2.65079</mass>
          <inertia>
            <ixx>0.002376</ixx>
            <ixy>0</ixy>
            <ixz>0</ixz>
            <iyy>0.001972</iyy>
            <iyz>0</iyz>
            <izz>0.001972</izz>
          </inertia>
        </inertial>
        <collision name='wheel_2_collision'>
          <pose>0.0916 0.090246 0.018979 0 -0 0</pose>
          <geometry>
            <mesh>
              <scale>0.001 0.001 0.001</scale>
              <uri>/home/arche/catkin_ws/src/arche_urdf_description/meshes/wheel_2.stl</uri>
            </mesh>
          </geometry>
          <surface>
            <contact>
              <ode/>
            </contact>
            <friction>
              <ode>
                <mu>0.2</mu>
                <mu2>0.2</mu2>
              </ode>
              <torsional>
                <ode/>
              </torsional>
            </friction>
            <bounce/>
          </surface>
          <max_contacts>10</max_contacts>
        </collision>
        <visual name='wheel_2_visual'>
          <pose>0.0916 0.090246 0.018979 0 -0 0</pose>
          <geometry>
            <mesh>
              <scale>0.001 0.001 0.001</scale>
              <uri>/home/arche/catkin_ws/src/arche_urdf_description/meshes/wheel_2.stl</uri>
            </mesh>
          </geometry>
          <material>
            <script>
              <name>Gazebo/Silver</name>
              <uri>file://media/materials/scripts/gazebo.material</uri>
            </script>
          </material>
        </visual>
        <self_collide>1</self_collide>
        <enable_wind>0</enable_wind>
        <kinematic>0</kinematic>
      </link>
      <joint name='wheel_3_joint' type='revolute'>
        <pose relative_to='base_link'>0.1695 0.157754 -0.018979 0 -0 0</pose>
        <parent>base_link</parent>
        <child>wheel_3</child>
        <axis>
          <xyz>1 0 0</xyz>
          <limit>
            <lower>-1e+16</lower>
            <upper>1e+16</upper>
          </limit>
          <dynamics>
            <spring_reference>0</spring_reference>
            <spring_stiffness>0</spring_stiffness>
          </dynamics>
        </axis>
      </joint>
      <link name='wheel_3'>
        <pose relative_to='wheel_3_joint'>0 0 0 0 -0 0</pose>
        <inertial>
          <pose>0.03 0 0 0 -0 0</pose>
          <mass>2.65079</mass>
          <inertia>
            <ixx>0.002376</ixx>
            <ixy>0</ixy>
            <ixz>0</ixz>
            <iyy>0.001972</iyy>
            <iyz>0</iyz>
            <izz>0.001972</izz>
          </inertia>
        </inertial>
        <collision name='wheel_3_collision'>
          <pose>-0.1695 -0.157754 0.018979 0 -0 0</pose>
          <geometry>
            <mesh>
              <scale>0.001 0.001 0.001</scale>
              <uri>/home/arche/catkin_ws/src/arche_urdf_description/meshes/wheel_3.stl</uri>
            </mesh>
          </geometry>
          <surface>
            <contact>
              <ode/>
            </contact>
            <friction>
              <ode>
                <mu>0.2</mu>
                <mu2>0.2</mu2>
              </ode>
              <torsional>
                <ode/>
              </torsional>
            </friction>
            <bounce/>
          </surface>
          <max_contacts>10</max_contacts>
        </collision>
        <visual name='wheel_3_visual'>
          <pose>-0.1695 -0.157754 0.018979 0 -0 0</pose>
          <geometry>
            <mesh>
              <scale>0.001 0.001 0.001</scale>
              <uri>/home/arche/catkin_ws/src/arche_urdf_description/meshes/wheel_3.stl</uri>
            </mesh>
          </geometry>
          <material>
            <script>
              <name>Gazebo/Silver</name>
              <uri>file://media/materials/scripts/gazebo.material</uri>
            </script>
          </material>
        </visual>
        <self_collide>1</self_collide>
        <enable_wind>0</enable_wind>
        <kinematic>0</kinematic>
      </link>
      <joint name='wheel_4_joint' type='revolute'>
        <pose relative_to='base_link'>-0.1695 0.157754 -0.018979 0 -0 0</pose>
        <parent>base_link</parent>
        <child>wheel_4</child>
        <axis>
          <xyz>-1 0 0</xyz>
          <limit>
            <lower>-1e+16</lower>
            <upper>1e+16</upper>
          </limit>
          <dynamics>
            <spring_reference>0</spring_reference>
            <spring_stiffness>0</spring_stiffness>
          </dynamics>
        </axis>
      </joint>
      <link name='wheel_4'>
        <pose relative_to='wheel_4_joint'>0 0 0 0 -0 0</pose>
        <inertial>
          <pose>-0.03 0 0 0 -0 0</pose>
          <mass>2.65079</mass>
          <inertia>
            <ixx>0.002376</ixx>
            <ixy>0</ixy>
            <ixz>0</ixz>
            <iyy>0.001972</iyy>
            <iyz>0</iyz>
            <izz>0.001972</izz>
          </inertia>
        </inertial>
        <collision name='wheel_4_collision'>
          <pose>0.1695 -0.157754 0.018979 0 -0 0</pose>
          <geometry>
            <mesh>
              <scale>0.001 0.001 0.001</scale>
              <uri>/home/arche/catkin_ws/src/arche_urdf_description/meshes/wheel_4.stl</uri>
            </mesh>
          </geometry>
          <surface>
            <contact>
              <ode/>
            </contact>
            <friction>
              <ode>
                <mu>0.2</mu>
                <mu2>0.2</mu2>
              </ode>
              <torsional>
                <ode/>
              </torsional>
            </friction>
            <bounce/>
          </surface>
          <max_contacts>10</max_contacts>
        </collision>
        <visual name='wheel_4_visual'>
          <pose>0.1695 -0.157754 0.018979 0 -0 0</pose>
          <geometry>
            <mesh>
              <scale>0.001 0.001 0.001</scale>
              <uri>/home/arche/catkin_ws/src/arche_urdf_description/meshes/wheel_4.stl</uri>
            </mesh>
          </geometry>
          <material>
            <script>
              <name>Gazebo/Silver</name>
              <uri>file://media/materials/scripts/gazebo.material</uri>
            </script>
          </material>
        </visual>
        <self_collide>1</self_collide>
        <enable_wind>0</enable_wind>
        <kinematic>0</kinematic>
      </link>
      <static>0</static>
      <plugin name='control' filename='libgazebo_ros_control.so'>
        <robotNamespace>/</robotNamespace>
      </plugin>
      <pose>0 0 0 0 -0 0</pose>
    </model>
    <state world_name='default'>
      <sim_time>0 0</sim_time>
      <real_time>0 0</real_time>
      <wall_time>1724767954 446602947</wall_time>
      <iterations>0</iterations>
      <model name='arche_urdf'>
        <pose>0 0 0.090041 0 -0 0</pose>
        <scale>1 1 1</scale>
        <link name='base_link'>
          <pose>0 0 0.090041 0 -0 0</pose>
          <velocity>0 0 0 0 -0 0</velocity>
          <acceleration>-1.20255 -0.24569 9.14636 -2.25326 -1.36054 -0.037266</acceleration>
          <wrench>-31.4487 -6.42524 239.194 0 -0 0</wrench>
        </link>
        <link name='wheel_1'>
          <pose>0.0916 -0.090246 0.071062 0 -0 0</pose>
          <velocity>0 0 0 0 -0 0</velocity>
          <acceleration>-1.81476 0.010006 1.56935 -1.04892 0.932147 -1.76082</acceleration>
          <wrench>-4.81056 0.026523 4.16002 0 -0 0</wrench>
        </link>
        <link name='wheel_2'>
          <pose>-0.0916 -0.090246 0.071062 0 -0 0</pose>
          <velocity>0 0 0 0 -0 0</velocity>
          <acceleration>-1.24361 -0.779536 12.4696 1.59438 0.123716 -2.51609</acceleration>
          <wrench>-3.29656 -2.06639 33.0543 0 -0 0</wrench>
        </link>
        <link name='wheel_3'>
          <pose>0.1695 0.157754 0.071062 0 -0 0</pose>
          <velocity>0 0 0 0 -0 0</velocity>
          <acceleration>-1.0132 0.544259 0.133639 2.79131 1.46431 -1.83544</acceleration>
          <wrench>-2.68579 1.44272 0.354249 0 -0 0</wrench>
        </link>
        <link name='wheel_4'>
          <pose>-0.1695 0.157754 0.071062 0 -0 0</pose>
          <velocity>0 0 0 0 -0 0</velocity>
          <acceleration>-0.551713 -0.683923 22.1553 1.49615 -1.34928 -1.66007</acceleration>
          <wrench>-1.46248 -1.81293 58.729 0 -0 0</wrench>
        </link>
      </model>
      <model name='ground_plane'>
        <pose>0 0 0 0 -0 0</pose>
        <scale>1 1 1</scale>
        <link name='link'>
          <pose>0 0 0 0 -0 0</pose>
          <velocity>0 0 0 0 -0 0</velocity>
          <acceleration>0 0 0 0 -0 0</acceleration>
          <wrench>0 0 0 0 -0 0</wrench>
        </link>
      </model>
      <light name='sun'>
        <pose>0 0 10 0 -0 0</pose>
      </light>
    </state>
    <gui fullscreen='0'>
      <camera name='user_camera'>
        <pose>3.01247 -2.72612 2.10976 0 0.479643 2.39619</pose>
        <view_controller>orbit</view_controller>
        <projection_type>perspective</projection_type>
      </camera>
    </gui>
  </world>
</sdf>
